Workbook

Sheet 説明
B2: 星約の賭場 — 二通貨経済 財務モデル（骨格 v0.1）
B4: 目的：第一通貨 Gil と 第二通貨 エテル(◈) の流入/シンクが横断で釣り合うかを見て、
B5: 給与・ショップ価格・為替レートを“設計・最適化”するための盤面。
B7: ■ 使い方
B8: 1. 「前提・レバー」シートの青字・黄色セルを埋める/弄る（人数・価格・レート等）。
B9: 2. 「Gil経済」「エテル経済」が月次の mint/sink を自動計算。
B10: 3. 「見通し」が12ヶ月先の供給推移、「ダッシュボード」が要点を表示。
B12: ■ 色の意味
B13: 青字 = 手で入れる入力値（シナリオで変える）
B14: 黒字 = 計算式 ／ 緑字 = 他シート参照
B15: 黄色セル = 要差し替え（Gill側に依頼 or 未定の値）
B17: ■ データの出どころ（役割分担）
... B26: 作成: 経理課 / 2026-06 ｜ 給与表 出典: サーバー「給与一覧」2026-05-28

Sheet 前提・レバー
A1: 前提・レバー（入力シート）
A2: 青字=入力 / 黄色=要差し替え。月額 = 単価 × 人数(件数/量)。
A4: Gil 流入①：給与（階級ロール・1人1つ／2週ごとに評価で昇降＝平均分布）
A5: 区分 | B5: 項目 | C5: 単価/給与 | D5: 人数/件数/量 | E5: 月額 | F5: 備考・データ源
A6: 階級 | B6: 星約者 | C6: 50000 | D6: 10 | E6: =C6*D6 | F6: 現行維持。人数=2週変動の平均
A7: 階級 | B7: 巡星者 | C7: 30000 | D7: 30 | E7: =C7*D7 | F7: ★主層。人数=2週変動の平均
A8: 階級 | B8: 堕星者 | C8: 20000 | D8: 8 | E8: =C8*D8 | F8: 現行維持。人数=平均
A9: 階級 | B9: 背律者 | C9: 0 | D9: 3 | E9: =C9*D9 | F9: 罰則(最下位)0。降格先=自動mint減
B10: 小計（給与_階級） | E10: =SUM(E6:E9)
A12: Gil 流入②：給与（役職ロール・重複可・固定分のみ）
A13: 区分 | B13: 項目 | C13: 単価/給与 | D13: 人数/件数/量 | E13: 月額 | F13: 備考・データ源
A14: 役職 | B14: モーセの十戒 | C14: 150000 | D14: 1 | E14: =C14*D14 | F14: 固定
A15: 役職 | B15: 天銀官 | C15: 70000 | D15: 1 | E15: =C15*D15 | F15: 固定
A16: 優遇 | B16: 星導官 | C16: 0 | D16: 6 | E16: =C16*D16 | F16: 完全歩合(基本給0)。理想6人=統括1+従者3-5+見習0-2・各上限12万
A17: 優遇 | B17: 審星官・特級 | C17: 90000 | D17: 1 | E17: =C17*D17 | F17: 顔役優遇:80000→90000 ＋評価歩合
A18: 優遇 | B18: 審星官・Ⅰ級 | C18: 60000 | D18: 1 | E18: =C18*D18 | F18: 顔役優遇:50000→60000
A19: 優遇 | B19: 審星官・Ⅱ級 | C19: 40000 | D19: 2 | E19: =C19*D19 | F19: 顔役優遇:30000→40000
A20: 優遇 | B20: 審星官・Ⅲ級 | C20: 25000 | D20: 2 | E20: =C20*D20 | F20: 顔役優遇:20000→25000
A21: 優遇 | B21: 審星官・見習い | C21: 15000 | D21: 3 | E21: =C21*D21 | F21: 顔役優遇:10000→15000
A22: 役職 | B22: 星祭官 | C22: 50000 | D22: 1 | E22: =C22*D22 | F22: 固定
A23: 役職 | B23: 印章官 | C23: 50000 | D23: 1 | E23: =C23*D23 | F23: ＋個人依頼＋鯖スタンプ×10000
A24: 役職 | B24: 星商官 | C24: 50000 | D24: 1 | E24: =C24*D24 | F24: 固定
A25: 役職 | B25: 幻戯官 | C25: 50000 | D25: 1 | E25: =C25*D25 | F25: 固定
... A29: 役職 | B29: 18禁 | C29: 0 | D29: 0 | E29: =C29*D29 | F29: 完全依頼制(変動)
B30: 小計（給与_役職） | E30: =SUM(E14:E29)
A32: Gil 流入③：給与（運営・Secret／含めると経済は健全側）
A33: 区分 | B33: 項目 | C33: 単価/給与 | D33: 人数/件数/量 | E33: 月額 | F33: 備考・データ源
A34: 運営 | B34: 原初星 | C34: 0 | D34: 1 | E34: =C34*D34 | F34: Secret＝要Gill
A35: 運営 | B35: 七星 | C35: 0 | D35: 1 | E35: =C35*D35 | F35: Secret＝要Gill
A36: 運営 | B36: 叛逆者 | C36: 0 | D36: 1 | E36: =C36*D36 | F36: Secret＝要Gill
A37: 運営 | B37: 執行官 | C37: 0 | D37: 1 | E37: =C37*D37 | F37: Secret＝要Gill
B38: 小計（給与_運営） | E38: =SUM(E34:E37)
A40: Gil 流入④：給与以外（Gill運用・額/頻度は要Gill or 我々が最適化）
A41: 区分 | B41: 項目 | C41: 単価/給与 | D41: 人数/件数/量 | E41: 月額 | F41: 備考・データ源
A42: 流入 | B42: 日記報酬 | C42: 5000 | D42: 20 | E42: =C42*D42 | F42: 刻:30日5万/100日10万/200日15万/300日20万/365日30万+ロール
A43: 流入 | B43: 招待報酬 | C43: 10000 | D43: 5 | E43: =C43*D43 | F43: 刻:5人5万/10人10万/+10万per10人/100人100万+ロール+Secret
A44: 流入 | B44: ランク報酬 | C44: 15000 | D44: 6 | E44: =C44*D44 | F44: 10Lvごと逓増マイルストーン
A45: 流入 | B45: サバブ達成 | C45: 40000 | D45: 3 | E45: =C45*D45 | F45: 刻:3〜5万×回数(仮4万)
A46: 流入 | B46: VC在席報酬 | C46: 100 | D46: 2000 | E46: =C46*D46 | F46: 刻:裁量で任せ→100Gil/h。会話VC限定
A47: 変動 | B47: 審星官 評価歩合 | C47: 1500 | D47: 40 | E47: =C47*D47 | F47: 見習500〜特級2500×枚数。実作業=ノーキャップ＋監視
...

Sheet Gil経済
A1: Gil経済（月次フロー）
A3: ◆ Gil 流入（mint / 月）
A4: 給与・階級 | B4: =SUM('前提・レバー'!$E$6:$E$9) | C4: Σ 人数×給与
A5: 給与・役職 | B5: =SUM('前提・レバー'!$E$14:$E$29) | C5: 重複可・固定分
A6: 給与・運営(Secret) | B6: =SUM('前提・レバー'!$E$34:$E$37) | C6: 要Gill
A7: 日記/招待/ブースト/VC | B7: =SUM('前提・レバー'!$E$42:$E$50) | C7: Gill運用
A8: Gil mint 合計 / 月 | B8: =SUM(B4:B7)
A10: ◆ Gil シンク（sink / 月）
A11: ショップ購入（手動） | B11: =SUM('前提・レバー'!$E$55:$E$69) | C11: 価格=我々
A12: カジノ両替 Gil→エテル（消滅） | B12: ='前提・レバー'!$C$76 | C12: Gilは消滅
A13: Gil sink 合計 / 月 | B13: =B11+B12
A15: ◆ カジノからの戻り（mint側）
A16: エテル→Gil 換金で戻るGil | B16: ='前提・レバー'!$C$77*(1-'前提・レバー'!$C$75)/'前提・レバー'!$C$74 | C16: (1-還光)×量÷レート
A18: ◆ 収支
A19: Gil 純増 / 月 | B19: =B8+B16-B13 | C19: mint+戻り−sink
A20: カジノ純吸収（Gil） | B20: =B12-B16 | C20: 両替流入−戻り
A21: カジノ吸収率（対Gil mint） | B21: =IF(B8=0,0,B20/B8) | C21: カジノがGil mintの何%を吸うか

Sheet エテル経済
A1: エテル経済（月次フロー・◈）
A3: ◆ 中間計算
A4: 月間 総ベット額（エテル） | B4: ='前提・レバー'!$C$81*'前提・レバー'!$C$82*'前提・レバー'!$C$83 | C4: 人数×回数×平均ベット
A5: ハウス吸収額（エテル） | B5: =B4*'前提・レバー'!$C$84 | C5: 総ベット×エッジ
A6: 福分け mint（エテル） | B6: ='前提・レバー'!$C$81*'前提・レバー'!$C$85*'前提・レバー'!$C$86 | C6: 人数×日額×日数
A8: ◆ エテル mint（発行 / 月）
A9: 福分け（daily） | B9: =B6
A10: Gil→エテル 両替で発行 | B10: ='前提・レバー'!$C$76/'前提・レバー'!$C$74 | C10: 両替Gil÷レート
A11: エテル mint 合計 / 月 | B11: =B9+B10
A13: ◆ エテル シンク（消滅 / 月）
A14: ハウス吸収の50%消滅 | B14: =B5*'前提・レバー'!$C$90 | C14: 残り50%はプールへ(供給内)
A15: エテル→Gil 換金で消滅 | B15: ='前提・レバー'!$C$77*(1-'前提・レバー'!$C$75) | C15: (1-還光)分がGil化し消滅
A16: エテル sink 合計 / 月 | B16: =B14+B15 | C16: 景品/累進奉納は別途
A18: ◆ 収支
A19: エテル 純増 / 月 | B19: =B11-B16 | C19: mint−sink
A20: プール流入（救済30%+JP20%） | B20: =B5*('前提・レバー'!$C$91+'前提・レバー'!$C$92) | C20: 供給内で循環

Sheet 見通し
A1: 見通し（12ヶ月・月次純増を一定と仮定した投影）
A2: 開始供給は青字で入力。月次純増は各経済シートから参照（簡易：一定）。
A4: Gil 開始供給 | B4: 5000000 | C4: ← 要Gill（現Gil総供給）
A5: エテル 開始供給 | B5: 90000 | C5: ← Bot監視の現エテル総供給
A7: 月 | B7: M0 | C7: M1 | D7: M2 | E7: M3 | F7: M4 | G7: M5 | H7: M6 | I7: M7 | J7: M8 | K7: M9 | L7: M10 | M7: M11 | N7: M12
A8: Gil 供給 | B8: =$B$4 | C8: =B8+'Gil経済'!$B$19 | D8: =C8+'Gil経済'!$B$19 | E8: =D8+'Gil経済'!$B$19 | F8: =E8+'Gil経済'!$B$19 | G8: =F8+'Gil経済'!$B$19 | H8: =G8+'Gil経済'!$B$19 | I8: =H8+'Gil経済'!$B$19 | J8: =I8+'Gil経済'!$B$19 | ... N8: =M8+'Gil経済'!$B$19
A9: エテル 供給 | B9: =$B$5 | C9: =B9+'エテル経済'!$B$19 | D9: =C9+'エテル経済'!$B$19 | E9: =D9+'エテル経済'!$B$19 | F9: =E9+'エテル経済'!$B$19 | G9: =F9+'エテル経済'!$B$19 | H9: =G9+'エテル経済'!$B$19 | I9: =H9+'エテル経済'!$B$19 | J9: =I9+'エテル経済'!$B$19 | ... N9: =M9+'エテル経済'!$B$19
A10: 均衡指標 | B10: =IF('Gil経済'!$B$19>0,"Gil増（吸収不足/インフレ寄り）",IF('Gil経済'!$B$19<0,"Gil減（吸いすぎ/デフレ寄り）","均衡"))

Sheet ダッシュボード
A1: ダッシュボード（要点）
A3: 指標 | B3: 値 | C3: 意味
A4: Gil mint 合計 / 月 | B4: ='Gil経済'!$B$8 | C4: サーバーが月に刷るGil
A5: Gil 純増 / 月 | B5: ='Gil経済'!$B$19 | C5: ＞0=インフレ寄り / ＜0=デフレ寄り
A6: カジノ純吸収（Gil） | B6: ='Gil経済'!$B$20 | C6: カジノが吸うGil
A7: カジノ吸収率（対Gil mint） | B7: =IF('Gil経済'!$B$8=0,0,'Gil経済'!$B$20/'Gil経済'!$B$8) | C7: 目標値を別途決める
A8: エテル mint 合計 / 月 | B8: ='エテル経済'!$B$11 | C8: カジノ内発行
A9: エテル 純増 / 月 | B9: ='エテル経済'!$B$19 | C9: ＞0=エテル増
A10: 為替レート R | B10: ='前提・レバー'!$C$74 | C10: 1エテル=?Gil（レバー）
A11: 還光率 h | B11: ='前提・レバー'!$C$75 | C11: レバー
A13: ■ 次に確定したいレバー
A14: ・為替レート R（接続後の本丸）
A15: ・ショップ各価格（Gilシンクの主力）
A16: ・VC在席レート（Gill側だが我々が最適化提案）
A17: ・カジノ吸収率の目標%（経済設計の北極星）

Sheet 取得時間
A1: 取得時間（time-to-earn）— 各財が“月収の何ヶ月分”か
A2: 値 = 価格 ÷ 月収。色: 緑=近い / 赤=遠い。価格・給与は前提シートと連動。数量△に依存しない設計盤面。
A4: 財 ＼ プロファイル | B4: 価格(Gil) | C4: 巡星者(主層) | D4: 星約者(無役) | E4: 星約者＋役職 | F4: 星約者＋顔役 | G4: 役職重ね持ち(富裕)
A5: 月収(Gil) → | C5: ='前提・レバー'!$C$7 | D5: ='前提・レバー'!$C$6 | E5: ='前提・レバー'!$C$6+'前提・レバー'!$C$22 | F5: ='前提・レバー'!$C$6+'前提・レバー'!$C$18 | G5: ='前提・レバー'!$C$6+'前提・レバー'!$C$15+'前提・レバー'!$C$22+'前提・レバー'!$C$23
A6: ='前提・レバー'!$B$55 | B6: ='前提・レバー'!$C$55 | C6: =IF(C$5=0,0,$B6/C$5) | D6: =IF(D$5=0,0,$B6/D$5) | E6: =IF(E$5=0,0,$B6/E$5) | F6: =IF(F$5=0,0,$B6/F$5) | G6: =IF(G$5=0,0,$B6/G$5)
A7: ='前提・レバー'!$B$56 | B7: ='前提・レバー'!$C$56 | C7: =IF(C$5=0,0,$B7/C$5) | D7: =IF(D$5=0,0,$B7/D$5) | E7: =IF(E$5=0,0,$B7/E$5) | F7: =IF(F$5=0,0,$B7/F$5) | G7: =IF(G$5=0,0,$B7/G$5)
A8: ='前提・レバー'!$B$57 | B8: ='前提・レバー'!$C$57 | C8: =IF(C$5=0,0,$B8/C$5) | D8: =IF(D$5=0,0,$B8/D$5) | E8: =IF(E$5=0,0,$B8/E$5) | F8: =IF(F$5=0,0,$B8/F$5) | G8: =IF(G$5=0,0,$B8/G$5)
A9: ='前提・レバー'!$B$58 | B9: ='前提・レバー'!$C$58 | C9: =IF(C$5=0,0,$B9/C$5) | D9: =IF(D$5=0,0,$B9/D$5) | E9: =IF(E$5=0,0,$B9/E$5) | F9: =IF(F$5=0,0,$B9/F$5) | G9: =IF(G$5=0,0,$B9/G$5)
A10: ='前提・レバー'!$B$59 | B10: ='前提・レバー'!$C$59 | C10: =IF(C$5=0,0,$B10/C$5) | D10: =IF(D$5=0,0,$B10/D$5) | E10: =IF(E$5=0,0,$B10/E$5) | F10: =IF(F$5=0,0,$B10/F$5) | G10: =IF(G$5=0,0,$B10/G$5)
A11: ='前提・レバー'!$B$60 | B11: ='前提・レバー'!$C$60 | C11: =IF(C$5=0,0,$B11/C$5) | D11: =IF(D$5=0,0,$B11/D$5) | E11: =IF(E$5=0,0,$B11/E$5) | F11: =IF(F$5=0,0,$B11/F$5) | G11: =IF(G$5=0,0,$B11/G$5)
A12: ='前提・レバー'!$B$61 | B12: ='前提・レバー'!$C$61 | C12: =IF(C$5=0,0,$B12/C$5) | D12: =IF(D$5=0,0,$B12/D$5) | E12: =IF(E$5=0,0,$B12/E$5) | F12: =IF(F$5=0,0,$B12/F$5) | G12: =IF(G$5=0,0,$B12/G$5)
A13: ='前提・レバー'!$B$62 | B13: ='前提・レバー'!$C$62 | C13: =IF(C$5=0,0,$B13/C$5) | D13: =IF(D$5=0,0,$B13/D$5) | E13: =IF(E$5=0,0,$B13/E$5) | F13: =IF(F$5=0,0,$B13/F$5) | G13: =IF(G$5=0,0,$B13/G$5)
A14: ='前提・レバー'!$B$63 | B14: ='前提・レバー'!$C$63 | C14: =IF(C$5=0,0,$B14/C$5) | D14: =IF(D$5=0,0,$B14/D$5) | E14: =IF(E$5=0,0,$B14/E$5) | F14: =IF(F$5=0,0,$B14/F$5) | G14: =IF(G$5=0,0,$B14/G$5)
A15: ='前提・レバー'!$B$64 | B15: ='前提・レバー'!$C$64 | C15: =IF(C$5=0,0,$B15/C$5) | D15: =IF(D$5=0,0,$B15/D$5) | E15: =IF(E$5=0,0,$B15/E$5) | F15: =IF(F$5=0,0,$B15/F$5) | G15: =IF(G$5=0,0,$B15/G$5)
A16: ='前提・レバー'!$B$65 | B16: ='前提・レバー'!$C$65 | C16: =IF(C$5=0,0,$B16/C$5) | D16: =IF(D$5=0,0,$B16/D$5) | E16: =IF(E$5=0,0,$B16/E$5) | F16: =IF(F$5=0,0,$B16/F$5) | G16: =IF(G$5=0,0,$B16/G$5)
A17: ='前提・レバー'!$B$66 | B17: ='前提・レバー'!$C$66 | C17: =IF(C$5=0,0,$B17/C$5) | D17: =IF(D$5=0,0,$B17/D$5) | E17: =IF(E$5=0,0,$B17/E$5) | F17: =IF(F$5=0,0,$B17/F$5) | G17: =IF(G$5=0,0,$B17/G$5)
A18: ='前提・レバー'!$B$67 | B18: ='前提・レバー'!$C$67 | C18: =IF(C$5=0,0,$B18/C$5) | D18: =IF(D$5=0,0,$B18/D$5) | E18: =IF(E$5=0,0,$B18/E$5) | F18: =IF(F$5=0,0,$B18/F$5) | G18: =IF(G$5=0,0,$B18/G$5)
A19: ='前提・レバー'!$B$68 | B19: ='前提・レバー'!$C$68 | C19: =IF(C$5=0,0,$B19/C$5) | D19: =IF(D$5=0,0,$B19/D$5) | E19: =IF(E$5=0,0,$B19/E$5) | F19: =IF(F$5=0,0,$B19/F$5) | G19: =IF(G$5=0,0,$B19/G$5)
A20: ='前提・レバー'!$B$69 | B20: ='前提・レバー'!$C$69 | C20: =IF(C$5=0,0,$B20/C$5) | D20: =IF(D$5=0,0,$B20/D$5) | E20: =IF(E$5=0,0,$B20/E$5) | F20: =IF(F$5=0,0,$B20/F$5) | G20: =IF(G$5=0,0,$B20/G$5)
A22: ■ 目標バンドの目安（主層基準）
A23: ・消耗品（反復）: 〜1ヶ月 … 気軽に何度も買える
A24: ・通行証・中位: 1〜3ヶ月 … 貯めれば手が届く
A25: ・中ステータス: 3〜6ヶ月 … 目標になる
A26: ・最上位ステータス: 6〜12ヶ月 … 憧れ・長期目標
A27: ・12ヶ月超: 原則 価格↓ or 給与↑ を検討
A28: ・※例外=鯨の蓄財シンク（限定カスタムロール等）: 意図的にバンド外。カジノ大勝ち/蓄財/イベント報酬を吸う最上位プレステージ。主層の取得時間で測らない
A29: ・※サブスク=通行証（継続課金）: 表の値は『月収の何倍/期の維持費』と読む。>1=収入だけでは維持不可＝富裕層向けの格差ゲート（意図的）
A30: ・設計原則: 格差はそこそこ許容（給与スプレッド維持・高額財は高く・過度な平準化はしない）

Sheet 収入設計
A1: 収入設計 — 非役職メンバーの稼ぎ口（floor design）
A2: 日記/招待/ランク報酬/VC は“役職なし”の主稼ぎ。役職持ちと採算をとり、主層に満足できる progression を。青字=設計入力。
A4: 収入源 | B4: 非役職カジュアル | C4: 非役職アクティブ | D4: 役職持ち(1職) | E4: 役職持ち(重ね)
A5: 階級ベース | B5: 30000 | C5: 30000 | D5: 50000 | E5: 50000
A6: 日記報酬 | B6: 8000 | C6: 15000 | D6: 10000 | E6: 10000
A7: 招待報酬 | B7: 0 | C7: 20000 | D7: 10000 | E7: 10000
A8: ランク報酬(月割) | B8: 3000 | C8: 8000 | D8: 5000 | E8: 5000
A9: VC在席 | B9: 5000 | C9: 10000 | D9: 8000 | E9: 10000
A10: 役職給 | B10: 0 | C10: 0 | D10: 50000 | E10: 170000
A11: 歩合 | B11: 0 | C11: 0 | D11: 0 | E11: 30000
A12: 月収 合計 | B12: =SUM(B5:B11) | C12: =SUM(C5:C11) | D12: =SUM(D5:D11) | E12: =SUM(E5:E11)
A13: 対 主層ベース(30k) 倍率 | B13: =B12/30000 | C13: =C12/30000 | D13: =D12/30000 | E13: =E12/30000
A15: ■ 設計方針
A16: ・非役職カジュアル: 素ベース×1.5前後（軽く触るだけでも上乗せ感）
A17: ・非役職アクティブ: 素ベース×2.5〜3（日記+招待+昇格で“頑張れば報われる”床）
A18: ・役職持ちとは更に差 → 格差はそこそこ維持（やりがい＋上を目指す動機）
A19: ・全faucetは消滅シンク前提＝派手に出してOK。Gil mint総額は前提シートで監視

Sheet 定員プラン
A1: 定員プラン — 各役職を何人雇えるか（予算 vs シンク）
A2: 青字=入力。役職の定員を変えると残予算が動く。月給/歩合/身分給は前提シートと連動。
A4: 給与予算 / 月（シンク連動） | B4: 2500000 | C4: 堅い1.3M〜現状2.5M〜カジノ後4M
A5: − 身分給（会員数で決まる固定費） | B5: ='前提・レバー'!E10
A6: ＝ 役職に回せる予算 | B6: =B4-B5
A8: 役職 | B8: 月給/人 | C8: 定員(計画) | D8: 月額
A9: モーセの十戒 | B9: ='前提・レバー'!C14 | C9: 1 | D9: =B9*C9
A10: 天銀官 | B10: ='前提・レバー'!C15 | C10: 1 | D10: =B10*C10
A11: 星導官 | B11: ='前提・レバー'!C16 | C11: 6 | D11: =B11*C11
A12: 審星官・特級 | B12: ='前提・レバー'!C17 | C12: 1 | D12: =B12*C12
A13: 審星官・Ⅰ級 | B13: ='前提・レバー'!C18 | C13: 1 | D13: =B13*C13
A14: 審星官・Ⅱ級 | B14: ='前提・レバー'!C19 | C14: 2 | D14: =B14*C14
A15: 審星官・Ⅲ級 | B15: ='前提・レバー'!C20 | C15: 2 | D15: =B15*C15
A16: 審星官・見習い | B16: ='前提・レバー'!C21 | C16: 3 | D16: =B16*C16
A17: 星祭官 | B17: ='前提・レバー'!C22 | C17: 1 | D17: =B17*C17
A18: 印章官 | B18: ='前提・レバー'!C23 | C18: 1 | D18: =B18*C18
A19: 星商官 | B19: ='前提・レバー'!C24 | C19: 1 | D19: =B19*C19
A20: 幻戯官 | B20: ='前提・レバー'!C25 | C20: 1 | D20: =B20*C20
... A24: 18禁 | B24: ='前提・レバー'!C29 | C24: 0 | D24: =B24*C24
A25: ※星導官=完全歩合(基本給0)。定員を増やしても固定費0・働いた分のみ上限12万/人
A26: 役職コスト 計 | D26: =SUM(D9:D24)
A27: ＋歩合（評価+星導+星賭） | D27: ='前提・レバー'!E47+'前提・レバー'!E48+'前提・レバー'!E49
A28: 残予算（役職予算−コスト−歩合） | D28: =B6-D26-D27
A30: ■ 読み方
A31: ・身分給(会員数)が先に予算を食う → 役職は“その残り”で雇う
A32: ・残予算マイナス＝シンク不足。カジノ接続 or サブスク増 or 会員増で枠が開く
A33: ・星導官は完全歩合＝定員を増やしても固定費は増えない（働いた分のみ）
