Workbook

Sheet 説明
B2: 星約の賭場 — 二通貨経済 財務モデル（骨格 v0.1）
B4: 目的：第一通貨 Gil と 第二通貨 エテル(◈) の流入/シンクが横断で釣り合うかを見て、
B5: 給与・ショップ価格・為替レートを“設計・最適化”するための盤面。
B7: ■ 使い方
B8: 1. 「前提・レバー」シートの青字・黄色セルを埋める/弄る（人数・価格・レート等）。
B9: 2. 「Gil経済」「エテル経済」が月次の mint/sink を自動計算。
B10: 3. 「見通し」が12ヶ月先の供給推移、「ダッシュボード」が要点を表示。
B12: ■ 色の意味
B13: 青字 = 手で入れる入力値（シナリオで変える）
B14: 黒字 = 計算式 ／ 緑字 = 他シート参照
B15: 黄色セル = 要差し替え（Gill側に依頼 or 未定の値）
B17: ■ データの出どころ（役割分担）
... B26: 作成: 経理課 / 2026-06 ｜ 給与表 出典: サーバー「給与一覧」2026-05-28

Sheet 前提・レバー
A1: 前提・レバー（入力シート）
A2: 青字=入力 / 黄色=要差し替え。月額 = 単価 × 人数(件数/量)。
A4: Gil 流入①：給与（階級ロール・1人1つ）
A5: 区分 | B5: 項目 | C5: 単価/給与 | D5: 人数/件数/量 | E5: 月額 | F5: 備考・データ源
A6: 階級 | B6: 星約者 | C6: 50000 | D6: 10 | E6: =C6*D6 | F6: 出典:給与一覧
A7: 階級 | B7: 巡星者 | C7: 30000 | D7: 15 | E7: =C7*D7 | F7: 出典:給与一覧
A8: 階級 | B8: 堕星者 | C8: 20000 | D8: 8 | E8: =C8*D8 | F8: 出典:給与一覧
A9: 階級 | B9: 背律者 | C9: 0 | D9: 3 | E9: =C9*D9 | F9: 出典:給与一覧(編集済0)
B10: 小計（給与_階級） | E10: =SUM(E6:E9)
A12: Gil 流入②：給与（役職ロール・重複可・固定分のみ）
A13: 区分 | B13: 項目 | C13: 単価/給与 | D13: 人数/件数/量 | E13: 月額 | F13: 備考・データ源
A14: 役職 | B14: モーセの十戒 | C14: 150000 | D14: 1 | E14: =C14*D14 | F14: 固定
A15: 役職 | B15: 星導官 | C15: 50000 | D15: 2 | E15: =C15*D15 | F15: ＋3000×面接回数(変動別枠)
A16: 役職 | B16: 審星官・特級 | C16: 80000 | D16: 1 | E16: =C16*D16 | F16: ＋歩合(変動別枠)
A17: 役職 | B17: 審星官・Ⅰ級 | C17: 50000 | D17: 1 | E17: =C17*D17 | F17: ＋歩合
A18: 役職 | B18: 審星官・Ⅱ級 | C18: 30000 | D18: 2 | E18: =C18*D18 | F18: ＋歩合
A19: 役職 | B19: 審星官・Ⅲ級 | C19: 20000 | D19: 2 | E19: =C19*D19 | F19: ＋歩合
A20: 役職 | B20: 審星官・見習い | C20: 10000 | D20: 3 | E20: =C20*D20 | F20: ＋歩合
A21: 役職 | B21: 星祭官 | C21: 50000 | D21: 1 | E21: =C21*D21 | F21: 固定
A22: 役職 | B22: 印章官 | C22: 50000 | D22: 1 | E22: =C22*D22 | F22: ＋個人依頼＋鯖スタンプ×10000
A23: 役職 | B23: 星商官 | C23: 50000 | D23: 1 | E23: =C23*D23 | F23: 固定
A24: 役職 | B24: 幻戯官 | C24: 50000 | D24: 1 | E24: =C24*D24 | F24: 固定
A25: 役職 | B25: 失星官 | C25: 30000 | D25: 1 | E25: =C25*D25 | F25: 固定
... A29: 役職 | B29: 18禁 | C29: 0 | D29: 0 | E29: =C29*D29 | F29: 完全依頼制(変動)
B30: 小計（給与_役職） | E30: =SUM(E14:E29)
A32: Gil 流入③：給与（運営・Secret／含めると経済は健全側）
A33: 区分 | B33: 項目 | C33: 単価/給与 | D33: 人数/件数/量 | E33: 月額 | F33: 備考・データ源
A34: 運営 | B34: 原初星 | C34: 0 | D34: 1 | E34: =C34*D34 | F34: Secret＝要Gill
A35: 運営 | B35: 七星 | C35: 0 | D35: 1 | E35: =C35*D35 | F35: Secret＝要Gill
A36: 運営 | B36: 叛逆者 | C36: 0 | D36: 1 | E36: =C36*D36 | F36: Secret＝要Gill
A37: 運営 | B37: 執行官 | C37: 0 | D37: 1 | E37: =C37*D37 | F37: Secret＝要Gill
B38: 小計（給与_運営） | E38: =SUM(E34:E37)
A40: Gil 流入④：給与以外（Gill運用・額/頻度は要Gill or 我々が最適化）
A41: 区分 | B41: 項目 | C41: 単価/給与 | D41: 人数/件数/量 | E41: 月額 | F41: 備考・データ源
A42: 流入 | B42: 日記達成 | C42: 5000 | D42: 30 | E42: =C42*D42 | F42: 支給額×月間達成件数
A43: 流入 | B43: 招待達成 | C43: 10000 | D43: 5 | E43: =C43*D43 | F43: 支給額×月間達成件数
A44: 流入 | B44: ブースト達成 | C44: 20000 | D44: 3 | E44: =C44*D44 | F44: 支給額×月間達成件数
A45: 流入 | B45: VC在席報酬 | C45: 100 | D45: 2000 | E45: =C45*D45 | F45: Gil/時間 × 月間総在席時間(h)
B46: 小計（Gil流入_その他） | E46: =SUM(E42:E45)
A48: Gil シンク：ショップ（手動運用・価格は我々が決める）
...

Sheet Gil経済
A1: Gil経済（月次フロー）
A3: ◆ Gil 流入（mint / 月）
A4: 給与・階級 | B4: =SUM('前提・レバー'!$E$6:$E$9) | C4: Σ 人数×給与
A5: 給与・役職 | B5: =SUM('前提・レバー'!$E$14:$E$29) | C5: 重複可・固定分
A6: 給与・運営(Secret) | B6: =SUM('前提・レバー'!$E$34:$E$37) | C6: 要Gill
A7: 日記/招待/ブースト/VC | B7: =SUM('前提・レバー'!$E$42:$E$45) | C7: Gill運用
A8: Gil mint 合計 / 月 | B8: =SUM(B4:B7)
A10: ◆ Gil シンク（sink / 月）
A11: ショップ購入（手動） | B11: =SUM('前提・レバー'!$E$50:$E$56) | C11: 価格=我々
A12: カジノ両替 Gil→エテル（消滅） | B12: ='前提・レバー'!$C$63 | C12: Gilは消滅
A13: Gil sink 合計 / 月 | B13: =B11+B12
A15: ◆ カジノからの戻り（mint側）
A16: エテル→Gil 換金で戻るGil | B16: ='前提・レバー'!$C$64*(1-'前提・レバー'!$C$62)/'前提・レバー'!$C$61 | C16: (1-還光)×量÷レート
A18: ◆ 収支
A19: Gil 純増 / 月 | B19: =B8+B16-B13 | C19: mint+戻り−sink
A20: カジノ純吸収（Gil） | B20: =B12-B16 | C20: 両替流入−戻り
A21: カジノ吸収率（対Gil mint） | B21: =IF(B8=0,0,B20/B8) | C21: カジノがGil mintの何%を吸うか

Sheet エテル経済
A1: エテル経済（月次フロー・◈）
A3: ◆ 中間計算
A4: 月間 総ベット額（エテル） | B4: ='前提・レバー'!$C$68*'前提・レバー'!$C$69*'前提・レバー'!$C$70 | C4: 人数×回数×平均ベット
A5: ハウス吸収額（エテル） | B5: =B4*'前提・レバー'!$C$71 | C5: 総ベット×エッジ
A6: 福分け mint（エテル） | B6: ='前提・レバー'!$C$68*'前提・レバー'!$C$72*'前提・レバー'!$C$73 | C6: 人数×日額×日数
A8: ◆ エテル mint（発行 / 月）
A9: 福分け（daily） | B9: =B6
A10: Gil→エテル 両替で発行 | B10: ='前提・レバー'!$C$63/'前提・レバー'!$C$61 | C10: 両替Gil÷レート
A11: エテル mint 合計 / 月 | B11: =B9+B10
A13: ◆ エテル シンク（消滅 / 月）
A14: ハウス吸収の50%消滅 | B14: =B5*'前提・レバー'!$C$77 | C14: 残り50%はプールへ(供給内)
A15: エテル→Gil 換金で消滅 | B15: ='前提・レバー'!$C$64*(1-'前提・レバー'!$C$62) | C15: (1-還光)分がGil化し消滅
A16: エテル sink 合計 / 月 | B16: =B14+B15 | C16: 景品/累進奉納は別途
A18: ◆ 収支
A19: エテル 純増 / 月 | B19: =B11-B16 | C19: mint−sink
A20: プール流入（救済30%+JP20%） | B20: =B5*('前提・レバー'!$C$78+'前提・レバー'!$C$79) | C20: 供給内で循環

Sheet 見通し
A1: 見通し（12ヶ月・月次純増を一定と仮定した投影）
A2: 開始供給は青字で入力。月次純増は各経済シートから参照（簡易：一定）。
A4: Gil 開始供給 | B4: 5000000 | C4: ← 要Gill（現Gil総供給）
A5: エテル 開始供給 | B5: 90000 | C5: ← Bot監視の現エテル総供給
A7: 月 | B7: M0 | C7: M1 | D7: M2 | E7: M3 | F7: M4 | G7: M5 | H7: M6 | I7: M7 | J7: M8 | K7: M9 | L7: M10 | M7: M11 | N7: M12
A8: Gil 供給 | B8: =$B$4 | C8: =B8+'Gil経済'!$B$19 | D8: =C8+'Gil経済'!$B$19 | E8: =D8+'Gil経済'!$B$19 | F8: =E8+'Gil経済'!$B$19 | G8: =F8+'Gil経済'!$B$19 | H8: =G8+'Gil経済'!$B$19 | I8: =H8+'Gil経済'!$B$19 | J8: =I8+'Gil経済'!$B$19 | ... N8: =M8+'Gil経済'!$B$19
A9: エテル 供給 | B9: =$B$5 | C9: =B9+'エテル経済'!$B$19 | D9: =C9+'エテル経済'!$B$19 | E9: =D9+'エテル経済'!$B$19 | F9: =E9+'エテル経済'!$B$19 | G9: =F9+'エテル経済'!$B$19 | H9: =G9+'エテル経済'!$B$19 | I9: =H9+'エテル経済'!$B$19 | J9: =I9+'エテル経済'!$B$19 | ... N9: =M9+'エテル経済'!$B$19
A10: 均衡指標 | B10: =IF('Gil経済'!$B$19>0,"Gil増（吸収不足/インフレ寄り）",IF('Gil経済'!$B$19<0,"Gil減（吸いすぎ/デフレ寄り）","均衡"))

Sheet ダッシュボード
A1: ダッシュボード（要点）
A3: 指標 | B3: 値 | C3: 意味
A4: Gil mint 合計 / 月 | B4: ='Gil経済'!$B$8 | C4: サーバーが月に刷るGil
A5: Gil 純増 / 月 | B5: ='Gil経済'!$B$19 | C5: ＞0=インフレ寄り / ＜0=デフレ寄り
A6: カジノ純吸収（Gil） | B6: ='Gil経済'!$B$20 | C6: カジノが吸うGil
A7: カジノ吸収率（対Gil mint） | B7: =IF('Gil経済'!$B$8=0,0,'Gil経済'!$B$20/'Gil経済'!$B$8) | C7: 目標値を別途決める
A8: エテル mint 合計 / 月 | B8: ='エテル経済'!$B$11 | C8: カジノ内発行
A9: エテル 純増 / 月 | B9: ='エテル経済'!$B$19 | C9: ＞0=エテル増
A10: 為替レート R | B10: ='前提・レバー'!$C$61 | C10: 1エテル=?Gil（レバー）
A11: 還光率 h | B11: ='前提・レバー'!$C$62 | C11: レバー
A13: ■ 次に確定したいレバー
A14: ・為替レート R（接続後の本丸）
A15: ・ショップ各価格（Gilシンクの主力）
A16: ・VC在席レート（Gill側だが我々が最適化提案）
A17: ・カジノ吸収率の目標%（経済設計の北極星）
